<robot
  name="rover_description">

  <link
    name="rover_base">
    <visual>
       <origin
        xyz="0.03 -0.62 0"
        rpy="0 0 0" />
      <geometry>
        <mesh
          filename="package://rover_arm_description/meshes/rover_base.STL" scale="0.3 0.3 0.3" />
      </geometry>
      <material
        name="">
        <color
          rgba="0.508039215686275 0.5517647058823529 0.6029411764705882 1" />
      </material>
      <origin
        xyz="0 0 0"
        rpy="0 0 0" />
    </visual>
  </link>

  <joint name="joint_arm" type="fixed">
    <origin rpy="0 0 1.57079632679" xyz="-0.16 0 0.28"/>
    <parent link="rover_base"/>
    <child link="arm_base_link"/>
  </joint>

  <link
    name="arm_base_link">
    <visual>
       <origin
        xyz="0 0 0"
        rpy="0 0 0" />
      <geometry>
        <cylinder length="0.01" radius="0.02"/>
      </geometry>
      <material
        name="">
        <color
          rgba="0.708039215686275 0.017647058823529 0.029411764705882 1" />
      </material>
      <origin
        xyz="0 0 0"
        rpy="0 0 0" />
    </visual>
  </link>

  <link
    name="link_1">
    <visual>
      <origin
        xyz="0.3807 0.65 -0.306"
        rpy="0 0 -0.16485" />
      <geometry>
        <mesh
          filename="package://rover_arm_description/meshes/link1.STL" />
      </geometry>
      <material
        name="">
        <color
          rgba="0.708039215686275 0.017647058823529 0.029411764705882 1" />
      </material>
    </visual>
    <collision>
      <origin
        xyz="0.3807 0.65 -0.306"
        rpy="0 0 -0.16485" />
      <geometry>
        <mesh
          filename="package://rover_arm_description/meshes/link1.STL" />
      </geometry>
    </collision>
  </link>

  <joint name="joint_1" type="revolute">
    <axis xyz="0 0 1"/>
    <limit effort="1000.0" lower="-1" upper="1" velocity="0.5"/>
    <origin rpy="0 0 0" xyz="0 0 0"/>
    <parent link="arm_base_link"/>
    <child link="link_1"/>
  </joint>

  <link
    name="link_2">
    <visual>
      <origin
        xyz="0.3807 0.677 -0.3653"
        rpy="0 0 -0.16485" />
      <geometry>
        <mesh
          filename="package://rover_arm_description/meshes/link2.STL" />
      </geometry>
      <material
        name="">
        <color
          rgba="0.05 0.05 0.08 1" />
      </material>
    </visual>
    <collision>
      <origin
        xyz="0.3807 0.677 -0.3653"
        rpy="0 0 -0.16485" />
      <geometry>
        <mesh
          filename="package://rover_arm_description/meshes/link2.STL" />
      </geometry>
    </collision>
  </link>

  <joint name="joint_2" type="revolute">
    <axis xyz="1 0 0"/>
    <limit effort="1000.0" lower="-0.65" upper="0.8" velocity="0.5"/>
    <origin rpy="0 0 0" xyz="0 -0.0268 0.0590"/>
    <parent link="link_1"/>
    <child link="link_2"/>
  </joint>

  <link
    name="link_2_1">
    <visual>
      <origin
        xyz="0.3807 0.677 -0.3653"
        rpy="0 0 -0.16485" />
      <geometry>
        <mesh
          filename="package://rover_arm_description/meshes/link21.STL" />
      </geometry>
      <material
        name="">
        <color
          rgba="0.708039215686275 0.017647058823529 0.029411764705882 1" />
      </material>
    </visual>
    <collision>
      <origin
        xyz="0.3807 0.677 -0.3653"
        rpy="0 0 -0.16485" />
      <geometry>
        <mesh
          filename="package://rover_arm_description/meshes/link21.STL" />
      </geometry>
    </collision>
  </link>

  <joint name="joint_2_1" type="fixed">
    <axis xyz="1 0 0"/>
    <limit effort="1000.0" lower="-0.65" upper="0.8" velocity="0.5"/>
    <origin rpy="0 0 0" xyz="0 0 0"/>
    <parent link="link_2"/>
    <child link="link_2_1"/>
  </joint>

  <link
    name="link_3">
    <visual>
      <origin
        xyz="0.3807 0.44 -0.9752"
        rpy="0 0 -0.16485" />
      <geometry>
        <mesh
          filename="package://rover_arm_description/meshes/link3.STL" />
      </geometry>
      <material
        name="">
        <color
          rgba="0.708039215686275 0.017647058823529 0.029411764705882 1" />
      </material>
    </visual>
    <collision>
      <origin
        xyz="0.3807 0.44 -0.9752"
        rpy="0 0 -0.16485" />
      <geometry>
        <mesh
          filename="package://rover_arm_description/meshes/link3.STL" />
      </geometry>
    </collision>
  </link>

  <joint name="joint_3" type="revolute">
    <axis xyz="1 0 0"/>
    <limit effort="1000.0" lower="-1" upper="0.8" velocity="0.5"/>
    <origin rpy="0.04 0 0" xyz="0 0.237 0.61"/>
    <parent link="link_2"/>
    <child link="link_3"/>
  </joint>

  <link
    name="link_4">
    <visual>
      <origin
        xyz="0.0006 0.26 -0.002"
        rpy="0.06 0.05 0" />
      <geometry>
        <mesh
          filename="package://rover_arm_description/meshes/link4.STL" />
      </geometry>
      <material
        name="">
        <color
          rgba="0.05 0.05 0.08 1" />
      </material>
    </visual>
    <collision>
      <origin
        xyz="0.0006 0.26 -0.002"
        rpy="0.06 0.05 0" />
      <geometry>
        <mesh
          filename="package://rover_arm_description/meshes/link4.STL" />
      </geometry>
    </collision>
  </link>

  <joint name="joint_4" type="revolute">
    <axis xyz="0 1 0"/>
    <limit effort="1000.0" lower="-3.14" upper="3.14" velocity="0.5"/>
    <origin rpy="-0.04 0 0" xyz="-0.003 0.13 -0.01"/>
    <parent link="link_3"/>
    <child link="link_4"/>
  </joint>

  <link
    name="link_5">
    <visual>
      <origin
        xyz="0 -0.009 0.001"
        rpy="0.064 0.05 0" />
      <geometry>
        <mesh
          filename="package://rover_arm_description/meshes/link5.STL" scale="1 1 0.9" />
      </geometry>
      <material
        name="">
        <color
          rgba="0.708039215686275 0.017647058823529 0.029411764705882 1" />
      </material>
    </visual>
    <collision>
      <origin
        xyz="0 -0.009 0.001"
        rpy="0.064 0.05 0" />
      <geometry>
        <mesh
          filename="package://rover_arm_description/meshes/link5.STL" />
      </geometry>
    </collision>
  </link>

  <joint name="joint_5" type="revolute">
    <axis xyz="0 0 1"/>
    <limit effort="1000.0" lower="-4.71079632679" upper="4.71079632679" velocity="0.5"/>
    <origin rpy="0 0 0" xyz="0 0.303 0"/>
    <parent link="link_4"/>
    <child link="link_5"/>
  </joint>

  <link
    name="link_6">
    <visual>
      <origin
        xyz="0 0 0"
        rpy="0 0 0" />
      <geometry>
        <cylinder length="0.01" radius="0.02"/>
      </geometry>
      <material
        name="">
        <color
          rgba="0.8039215686275 0.917647058823529 0.929411764705882 1" />
      </material>
    </visual>
    <collision>
      <origin
        xyz="0 0 0"
        rpy="0 0 0" />
      <geometry>
        <cylinder length="0.01" radius="0.02"/>
      </geometry>
    </collision>
  </link>

  <joint name="joint_6" type="revolute">
    <axis xyz="0 0 1"/>
    <limit effort="1000.0" lower="-3.14" upper="3.14" velocity="0.5"/>
    <origin rpy="-1.57079632679 0 0" xyz="0 0.035 0"/>
    <parent link="link_5"/>
    <child link="link_6"/>
  </joint>

  <link
    name="gripper_base">
    <visual>
      <origin
        xyz="0 0 0"
        rpy="0 0 0" />
      <geometry>
        <cylinder length="0.001" radius="0.02"/>
      </geometry>
      <material
        name="">
        <color
          rgba="0.8039215686275 0.917647058823529 0.929411764705882 1" />
      </material>
    </visual>
  </link>

  <joint name="gripper_base_joint" type="fixed">
    <origin rpy="0 0 0" xyz="0 0 0.05"/>
    <parent link="link_6"/>
    <child link="gripper_base"/>
  </joint>

  <link
    name="gripper">
    <visual>
      <origin
        xyz="0 0 0"
        rpy="0 0 0" />
      <geometry>
        <cylinder length="0.001" radius="0.02"/>
      </geometry>
      <material
        name="">
        <color
          rgba="0.8039215686275 0.917647058823529 0.929411764705882 1" />
      </material>
    </visual>
  </link>

  <joint name="gripper_joint" type="fixed">
    <origin rpy="0 0 0" xyz="0 0 0.01"/>
    <parent link="gripper_base"/>
    <child link="gripper"/>
  </joint>
</robot>
